Workbook

Sheet Basic Objective Test
A1: PuzzleBot LLM–VLM–ROS2 | Basic Objective Test Plan (75 Trials)
A2: 1.LLM Latency (ms): Time taken to convert the natural language command into a structured navigation intent and target label. 2.DINO Latency (ms): Time when the target is successfully detected for the first time 3.Depth Latency (ms): Time when the target was successfully detected for the first time based on depth estimation from the image 4.Nav Total Latency (ms): The total navigation time from receiving the target at the navigation_node and starting navigation to the robot determining whether it has arrived or stopped. 5.Total time (s): Measure the total end-to-end time from the start of the input command to the robot's final stop. 6.Final Dist to Target (m): Measure the straight-line distance between the robot and the actual target object when the robot stops. Pass Criteria: Success to arrive at the target and navigate to within 0.5 m of target
A3: Trial # | B3: Room Type | C3: Condition Group | D3: Rep # | E3: Lighting (lux)(use LightMeterApp) | F3: Distractor Objects | G3: Navigated to Correct Target? | H3: Target Object | I3: Natural Language Command | J3: LLM Extracted Label | K3: Label Match? (Y/N) | L3: LLM Latency (ms) | M3: DINO Latency (ms) | N3: Depth Latency (ms) | O3: Nav Total Latency (ms) | P3: Toal time(s) | Q3: Final Dist to Target (m) | R3: Dist Threshold (m) | S3: Trial Result | T3: PASS / FAIL | U3: Failure Reason | V3: Observations & Notes
A4: 1 | B4: Office | C4: Cup | D4: 1 | E4: 800 ± 20 lux | F4: Bag, Chair, Box, Notebook | G4: Yes | H4: Cup | I4: go to the Cup | J4: Cup | K4: Y | L4: 11544 | M4: 1502 | N4: 82 | O4: 13007 | P4: 24.28s | Q4: 0.331 | R4: 0.55 | S4: Success | T4: =IF(S4="Pending","Pending",IF(AND(S4="Success",Q4<=0.55),"PASS","FAIL")) -> PASS
A5: 2 | B5: Office | C5: Cup | D5: 2 | E5: 800 ± 20 lux | F5: Bag, Chair, Box, Notebook | G5: Yes | H5: Cup | I5: move to the Cup | J5: Cup | K5: Y | L5: 1888 | M5: 370 | N5: 56 | O5: 10669 | P5: 12.85s | Q5: 0.355 | R5: 0.55 | S5: Success | T5: =IF(S5="Pending","Pending",IF(AND(S5="Success",Q5<=0.55),"PASS","FAIL")) -> PASS
A6: 3 | B6: Office | C6: Cup | D6: 3 | E6: 800 ± 20 lux | F6: Bag, Chair, Box, Notebook | G6: Yes | H6: Cup | I6: navigate to the Cup | J6: Cup | K6: Y | L6: 1824 | M6: 355 | N6: 53 | O6: 10732 | P6: 12.81s | Q6: 0.353 | R6: 0.55 | S6: Success | T6: =IF(S6="Pending","Pending",IF(AND(S6="Success",Q6<=0.55),"PASS","FAIL")) -> PASS
A7: 4 | B7: Office | C7: Cup | D7: 4 | E7: 800 ± 20 lux | F7: Bag, Chair, Box, Notebook | G7: Yes | H7: Cup | I7: approach the Cup | J7: Cup | K7: Y | L7: 1808 | M7: 377 | N7: 58 | O7: 10587 | P7: 12.68s | Q7: 0.336 | R7: 0.55 | S7: Success | T7: =IF(S7="Pending","Pending",IF(AND(S7="Success",Q7<=0.55),"PASS","FAIL")) -> PASS
A8: 5 | B8: Office | C8: Cup | D8: 5 | E8: 800 ± 20 lux | F8: Bag, Chair, Box, Notebook | G8: Yes | H8: Cup | I8: head to the Cup | J8: Cup | K8: Y | L8: 1794 | M8: 329 | N8: 55 | O8: 12590 | P8: 14.68s | Q8: 0.125 | R8: 0.55 | S8: Success | T8: =IF(S8="Pending","Pending",IF(AND(S8="Success",Q8<=0.55),"PASS","FAIL")) -> PASS
A9: 6 | B9: Office | C9: Shoe | D9: 1 | E9: 800 ± 20 lux | F9: Bag, Chair, Box, Notebook, Cup | G9: Yes | H9: Shoe | I9: go to the Shoe | J9: Shoe | K9: Y | L9: 1969 | M9: 371 | N9: 56 | O9: 18416 | P9: 20.85s | Q9: 0.25 | R9: 0.55 | S9: Success | T9: =IF(S9="Pending","Pending",IF(AND(S9="Success",Q9<=0.55),"PASS","FAIL")) -> PASS
A10: 7 | B10: Office | C10: Shoe | D10: 2 | E10: 800 ± 20 lux | F10: Bag, Chair, Box, Notebook, Cup | G10: Yes | H10: Shoe | I10: move to the Shoe | J10: Shoe | K10: Y | L10: 1950 | M10: 339 | N10: 54 | O10: 18898 | P10: 21.13s | Q10: 0.204 | R10: 0.55 | S10: Success | T10: =IF(S10="Pending","Pending",IF(AND(S10="Success",Q10<=0.55),"PASS","FAIL")) -> PASS
A11: 8 | B11: Office | C11: Shoe | D11: 3 | E11: 800 ± 20 lux | F11: Bag, Chair, Box, Notebook, Cup | G11: Yes | H11: Shoe | I11: navigate to the Shoe | J11: Shoe | K11: Y | L11: 1958 | M11: 377 | N11: 58 | O11: 19268 | P11: 21.62s | Q11: 0.168 | R11: 0.55 | S11: Success | T11: =IF(S11="Pending","Pending",IF(AND(S11="Success",Q11<=0.55),"PASS","FAIL")) -> PASS
A12: 9 | B12: Office | C12: Shoe | D12: 4 | E12: 800 ± 20 lux | F12: Bag, Chair, Box, Notebook, Cup | G12: Yes | H12: Shoe | I12: approach the Shoe | J12: Shoe | K12: Y | L12: 1910 | M12: 367 | N12: 55 | O12: 19946 | P12: 22.10s | Q12: 0.16 | R12: 0.55 | S12: Success | T12: =IF(S12="Pending","Pending",IF(AND(S12="Success",Q12<=0.55),"PASS","FAIL")) -> PASS
A13: 10 | B13: Office | C13: Shoe | D13: 5 | E13: 800 ± 20 lux | F13: Bag, Chair, Box, Notebook, Cup | G13: Yes | H13: Shoe | I13: head to the Shoe | J13: Shoe | K13: Y | L13: 1823 | M13: 374 | N13: 58 | O13: 17881 | P13: 20.13s | Q13: 0.334 | R13: 0.55 | S13: Success | T13: =IF(S13="Pending","Pending",IF(AND(S13="Success",Q13<=0.55),"PASS","FAIL")) -> PASS
A14: 11 | B14: Office | C14: Box | D14: 1 | E14: 800 ± 20 lux | F14: Bag, Chair, Cup, Notebook | G14: Yes | H14: Box | I14: go to the Box | J14: Box | K14: Y | L14: 1808 | M14: 378 | N14: 63 | O14: 22452 | P14: 24.85s | Q14: 0.339 | R14: 0.55 | S14: Success | T14: =IF(S14="Pending","Pending",IF(AND(S14="Success",Q14<=0.55),"PASS","FAIL")) -> PASS
A15: 12 | B15: Office | C15: Box | D15: 2 | E15: 800 ± 20 lux | F15: Bag, Chair, Cup, Notebook | G15: Yes | H15: Box | I15: move to the Box | J15: Box | K15: Y | L15: 1806 | M15: 372 | N15: 58 | O15: 20823 | P15: 23.02s | Q15: 0.413 | R15: 0.55 | S15: Success | T15: =IF(S15="Pending","Pending",IF(AND(S15="Success",Q15<=0.55),"PASS","FAIL")) -> PASS
... A43: 15 | B43: Office | C43: Box | D43: 5 | E43: 500 ± 20 lux | F43: Chair, Bag, Notebook | G43: Yes | H43: Box | I43: head to the Box | J43: Box | K43: Y | L43: 1833 | M43: 373 | N43: 59 | O43: 17583 | P43: 19.72s | Q43: 0.276 | R43: 0.55 | S43: Success | T43: =IF(S43="Pending","Pending",IF(AND(S43="Success",Q43<=0.55),"PASS","FAIL")) -> PASS
A44: 16 | B44: Office | C44: Bag | D44: 1 | E44: 500 ± 20 lux | F44: Chair, Box, Notebook, Cup | G44: Yes | H44: Bag | I44: go to the Bag | J44: Bag | K44: Y | L44: 1814 | M44: 370 | N44: 58 | O44: 15383 | P44: 17.53s | Q44: 0.689 | R44: 0.55 | S44: Success | T44: =IF(S44="Pending","Pending",IF(AND(S44="Success",Q44<=0.55),"PASS","FAIL")) -> FAIL | U44: Failures involving the "Bag" target under 500-lux lighting conditions were primarily due to excessive final stopping distances rather than errors in semantic understanding or object recognition. Logs indicate that the LLM correctly identified the bag as the navigation target and that DINO/NCC consistently detected it; the robot's final state was recorded as ARRIVED. However, the navigation node's arrival determination relies not only on a 0.50 m distance threshold but also on visual arrival criteria based on the detection box's area and the position of its bottom edge. When the bag occupied a large area within the image, the system triggered the VISUAL_ARRIVED state and halted while the estimated distance was still approximately 0.7 m. Since the experimental success threshold was set at 0.55 m, this premature stop resulted in a final distance exceeding the threshold, leading to a "FAIL" classification. The bag is inherently a soft, irregular object; its boundaries and bottom contact points are less stable than those of rigid objects like cups, boxes, or notebooks. Under 500-lux lighting, the detection box for the bag was prone to expanding or encompassing shadows and folds, causing the visual area criterion to be met prematurely—even though the estimated depth had not yet dropped to the 0.50 m stopping threshold. Consequently, while the robot successfully approached the bag, its stopping position was overly conservative; final distances clustered between 0.62 m and 0.69 m, exceeding the 0.55 m success criterion.
A45: 17 | B45: Office | C45: Bag | D45: 2 | E45: 500 ± 20 lux | F45: Chair, Box, Notebook, Cup | G45: Yes | H45: Bag | I45: move to the Bag | J45: Bag | K45: Y | L45: 1014 | M45: 370 | N45: 59 | O45: 16038 | P45: 18.43s | Q45: 0.678 | R45: 0.55 | S45: Success | T45: =IF(S45="Pending","Pending",IF(AND(S45="Success",Q45<=0.55),"PASS","FAIL")) -> FAIL | U45: Failures involving the "Bag" target under 500-lux lighting conditions were primarily due to excessive final stopping distances rather than errors in semantic understanding or object recognition. Logs indicate that the LLM correctly identified the bag as the navigation target and that DINO/NCC consistently detected it; the robot's final state was recorded as ARRIVED. However, the navigation node's arrival determination relies not only on a 0.50 m distance threshold but also on visual arrival criteria based on the detection box's area and the position of its bottom edge. When the bag occupied a large area within the image, the system triggered the VISUAL_ARRIVED state and halted while the estimated distance was still approximately 0.7 m. Since the experimental success threshold was set at 0.55 m, this premature stop resulted in a final distance exceeding the threshold, leading to a "FAIL" classification. The bag is inherently a soft, irregular object; its boundaries and bottom contact points are less stable than those of rigid objects like cups, boxes, or notebooks. Under 500-lux lighting, the detection box for the bag was prone to expanding or encompassing shadows and folds, causing the visual area criterion to be met prematurely—even though the estimated depth had not yet dropped to the 0.50 m stopping threshold. Consequently, while the robot successfully approached the bag, its stopping position was overly conservative; final distances clustered between 0.62 m and 0.69 m, exceeding the 0.55 m success criterion.
A46: 18 | B46: Office | C46: Bag | D46: 3 | E46: 500 ± 20 lux | F46: Chair, Box, Notebook, Cup | G46: Yes | H46: Bag | I46: navigate to the Bag | J46: Bag | K46: Y | L46: 1765 | M46: 361 | N46: 56 | O46: 15799 | P46: 18.02s | Q46: 0.626 | R46: 0.55 | S46: Success | T46: =IF(S46="Pending","Pending",IF(AND(S46="Success",Q46<=0.55),"PASS","FAIL")) -> FAIL | U46: Failures involving the "Bag" target under 500-lux lighting conditions were primarily due to excessive final stopping distances rather than errors in semantic understanding or object recognition. Logs indicate that the LLM correctly identified the bag as the navigation target and that DINO/NCC consistently detected it; the robot's final state was recorded as ARRIVED. However, the navigation node's arrival determination relies not only on a 0.50 m distance threshold but also on visual arrival criteria based on the detection box's area and the position of its bottom edge. When the bag occupied a large area within the image, the system triggered the VISUAL_ARRIVED state and halted while the estimated distance was still approximately 0.7 m. Since the experimental success threshold was set at 0.55 m, this premature stop resulted in a final distance exceeding the threshold, leading to a "FAIL" classification. The bag is inherently a soft, irregular object; its boundaries and bottom contact points are less stable than those of rigid objects like cups, boxes, or notebooks. Under 500-lux lighting, the detection box for the bag was prone to expanding or encompassing shadows and folds, causing the visual area criterion to be met prematurely—even though the estimated depth had not yet dropped to the 0.50 m stopping threshold. Consequently, while the robot successfully approached the bag, its stopping position was overly conservative; final distances clustered between 0.62 m and 0.69 m, exceeding the 0.55 m success criterion.
A47: 19 | B47: Office | C47: Bag | D47: 4 | E47: 500 ± 20 lux | F47: Chair, Box, Notebook, Cup | G47: Yes | H47: Bag | I47: approach the Bag | J47: Bag | K47: Y | L47: 1802 | M47: 377 | N47: 60 | O47: 15459 | P47: 17.80s | Q47: 0.624 | R47: 0.55 | S47: Success | T47: =IF(S47="Pending","Pending",IF(AND(S47="Success",Q47<=0.55),"PASS","FAIL")) -> FAIL | U47: Failures involving the "Bag" target under 500-lux lighting conditions were primarily due to excessive final stopping distances rather than errors in semantic understanding or object recognition. Logs indicate that the LLM correctly identified the bag as the navigation target and that DINO/NCC consistently detected it; the robot's final state was recorded as ARRIVED. However, the navigation node's arrival determination relies not only on a 0.50 m distance threshold but also on visual arrival criteria based on the detection box's area and the position of its bottom edge. When the bag occupied a large area within the image, the system triggered the VISUAL_ARRIVED state and halted while the estimated distance was still approximately 0.7 m. Since the experimental success threshold was set at 0.55 m, this premature stop resulted in a final distance exceeding the threshold, leading to a "FAIL" classification. The bag is inherently a soft, irregular object; its boundaries and bottom contact points are less stable than those of rigid objects like cups, boxes, or notebooks. Under 500-lux lighting, the detection box for the bag was prone to expanding or encompassing shadows and folds, causing the visual area criterion to be met prematurely—even though the estimated depth had not yet dropped to the 0.50 m stopping threshold. Consequently, while the robot successfully approached the bag, its stopping position was overly conservative; final distances clustered between 0.62 m and 0.69 m, exceeding the 0.55 m success criterion.
A48: 20 | B48: Office | C48: Bag | D48: 5 | E48: 500 ± 20 lux | F48: Chair, Box, Notebook, Cup | G48: Yes | H48: Bag | I48: head to the Bag | J48: Bag | K48: Y | L48: 1811 | M48: 367 | N48: 57 | O48: 17694 | P48: 19.95s | Q48: 0.505 | R48: 0.55 | S48: Success | T48: =IF(S48="Pending","Pending",IF(AND(S48="Success",Q48<=0.55),"PASS","FAIL")) -> PASS
A49: 21 | B49: Office | C49: Notebook | D49: 1 | E49: 500 ± 20 lux | F49: Chair, Box, Bag, Cup | G49: Yes | H49: Notebook | I49: go to the Notebook | J49: Notebook | K49: Y | L49: 1793 | M49: 373 | N49: 61 | O49: 15481 | P49: 18.00s | Q49: 0.315 | R49: 0.55 | S49: Success | T49: =IF(S49="Pending","Pending",IF(AND(S49="Success",Q49<=0.55),"PASS","FAIL")) -> PASS
A50: 22 | B50: Office | C50: Notebook | D50: 2 | E50: 500 ± 20 lux | F50: Chair, Box, Bag, Cup | G50: Yes | H50: Notebook | I50: move to the Notebook | J50: Notebook | K50: Y | L50: 1805 | M50: 371 | N50: 59 | O50: 18136 | P50: 20.48s | Q50: 0.184 | R50: 0.55 | S50: Success | T50: =IF(S50="Pending","Pending",IF(AND(S50="Success",Q50<=0.55),"PASS","FAIL")) -> PASS
A51: 23 | B51: Office | C51: Notebook | D51: 3 | E51: 500 ± 20 lux | F51: Chair, Box, Bag, Cup | G51: Yes | H51: Notebook | I51: navigate to the Notebook | J51: Notebook | K51: Y | L51: 1779 | M51: 376 | N51: 60 | O51: 14222 | P51: 16.43s | Q51: 0.348 | R51: 0.55 | S51: Success | T51: =IF(S51="Pending","Pending",IF(AND(S51="Success",Q51<=0.55),"PASS","FAIL")) -> PASS
A52: 24 | B52: Office | C52: Notebook | D52: 4 | E52: 500 ± 20 lux | F52: Chair, Box, Bag, Cup | G52: Yes | H52: Notebook | I52: approach the Notebook | J52: Notebook | K52: Y | L52: 1529 | M52: 362 | N52: 56 | O52: 14229 | P52: 16.40s | Q52: 0.411 | R52: 0.55 | S52: Success | T52: =IF(S52="Pending","Pending",IF(AND(S52="Success",Q52<=0.55),"PASS","FAIL")) -> PASS
A53: 25 | B53: Office | C53: Notebook | D53: 5 | E53: 500 ± 20 lux | F53: Chair, Box, Bag, Cup | G53: Yes | H53: Notebook | I53: head to the Notebook | J53: Notebook | K53: Y | L53: 1773 | M53: 367 | N53: 57 | O53: 15345 | P53: 17.47s | Q53: 0.341 | R53: 0.55 | S53: Success | T53: =IF(S53="Pending","Pending",IF(AND(S53="Success",Q53<=0.55),"PASS","FAIL")) -> PASS
A54: 1 | B54: Office | C54: Cup | D54: 1 | E54: 200 ± 20 lux | F54: Chair, Bag, Box | G54: Yes | H54: Cup | I54: go to the Cup | J54: Cup | K54: Y | L54: 7610 | M54: 1050 | N54: 89 | O54: 16456 | P54: 23.83s | Q54: 0.376 | R54: 0.55 | S54: Success | T54: =IF(S54="Pending","Pending",IF(AND(S54="Success",Q54<=0.55),"PASS","FAIL")) -> PASS | V54: The first LLM request showed a higher latency due to cold-start overhead. Subsequent intent extraction calls stabilised at around 1.8-2.0 seconds.
A55: 2 | B55: Office | C55: Cup | D55: 2 | E55: 200 ± 20 lux | F55: Chair, Bag, Box | G55: Yes | H55: Cup | I55: move to the Cup | J55: Cup | K55: Y | L55: 1794 | M55: 380 | N55: 59 | O55: 12638 | P55: 13.58s | Q55: 0.355 | R55: 0.55 | S55: Success | T55: =IF(S55="Pending","Pending",IF(AND(S55="Success",Q55<=0.55),"PASS","FAIL")) -> PASS
A56: 3 | B56: Office | C56: Cup | D56: 3 | E56: 200 ± 20 lux | F56: Chair, Bag, Box | G56: Yes | H56: Cup | I56: navigate to the Cup | J56: Cup | K56: Y | L56: 1789 | M56: 375 | N56: 59 | O56: 12817 | P56: 14.65s | Q56: 0.376 | R56: 0.55 | S56: Success | T56: =IF(S56="Pending","Pending",IF(AND(S56="Success",Q56<=0.55),"PASS","FAIL")) -> PASS
A57: 4 | B57: Office | C57: Cup | D57: 4 | E57: 200 ± 20 lux | F57: Chair, Bag, Box | G57: Yes | H57: Cup | I57: approach the Cup | J57: Cup | K57: Y | L57: 1970 | M57: 379 | N57: 57 | O57: 13550 | P57: 15.37s | Q57: 0.336 | R57: 0.55 | S57: Success | T57: =IF(S57="Pending","Pending",IF(AND(S57="Success",Q57<=0.55),"PASS","FAIL")) -> PASS
A58: 5 | B58: Office | C58: Cup | D58: 5 | E58: 200 ± 20 lux | F58: Chair, Bag, Box | G58: Yes | H58: Cup | I58: head to the Cup | J58: Cup | K58: Y | L58: 1760 | M58: 379 | N58: 58 | O58: 13652 | P58: 15.48s | Q58: 0.341 | R58: 0.55 | S58: Success | T58: =IF(S58="Pending","Pending",IF(AND(S58="Success",Q58<=0.55),"PASS","FAIL")) -> PASS
A59: 6 | B59: Office | C59: Shoe | D59: 1 | E59: 200 ± 20 lux | F59: Chair, Bag, Box, Cup | G59: Yes | H59: Shoe | I59: go to the Shoe | J59: Shoe | K59: Y | L59: 6004 | M59: 375 | N59: 59 | O59: 17147 | P59: 22.95s | Q59: 0.331 | R59: 0.55 | S59: Success | T59: =IF(S59="Pending","Pending",IF(AND(S59="Success",Q59<=0.55),"PASS","FAIL")) -> PASS
A60: 7 | B60: Office | C60: Shoe | D60: 2 | E60: 200 ± 20 lux | F60: Chair, Bag, Box, Cup | G60: Yes | H60: Shoe | I60: move to the Shoe | J60: Shoe | K60: Y | L60: 1781 | M60: 381 | N60: 59 | O60: 16514 | P60: 18.35s | Q60: 0.357 | R60: 0.55 | S60: Success | T60: =IF(S60="Pending","Pending",IF(AND(S60="Success",Q60<=0.55),"PASS","FAIL")) -> PASS
A61: 8 | B61: Office | C61: Shoe | D61: 3 | E61: 200 ± 20 lux | F61: Chair, Bag, Box, Cup | G61: Yes | H61: Shoe | I61: navigate to the Shoe | J61: Shoe | K61: Y | L61: 1771 | M61: 368 | N61: 56 | O61: 17297 | P61: 19.13s | Q61: 0.311 | R61: 0.55 | S61: Success | T61: =IF(S61="Pending","Pending",IF(AND(S61="Success",Q61<=0.55),"PASS","FAIL")) -> PASS
A62: 9 | B62: Office | C62: Shoe | D62: 4 | E62: 200 ± 20 lux | F62: Chair, Bag, Box, Cup | G62: Yes | H62: Shoe | I62: approach the Shoe | J62: Shoe | K62: Y | L62: 1777 | M62: 383 | N62: 61 | O62: 17183 | P62: 19.28s | Q62: 0.147 | R62: 0.55 | S62: Success | T62: =IF(S62="Pending","Pending",IF(AND(S62="Success",Q62<=0.55),"PASS","FAIL")) -> PASS
A63: 10 | B63: Office | C63: Shoe | D63: 5 | E63: 200 ± 20 lux | F63: Chair, Bag, Box, Cup | G63: Yes | H63: Shoe | I63: head to the Shoe | J63: Shoe | K63: Y | L63: 4790 | M63: 376 | N63: 58 | O63: 16998 | P63: 24.00s | Q63: 0.179 | R63: 0.55 | S63: Success | T63: =IF(S63="Pending","Pending",IF(AND(S63="Success",Q63<=0.55),"PASS","FAIL")) -> PASS
A64: 11 | B64: Office | C64: Box | D64: 1 | E64: 200 ± 20 lux | F64: Chair, Bag, Shoe, Cup | G64: Yes | H64: Box | I64: go to the Box | J64: Box | K64: Y | L64: 1425 | M64: 992 | N64: 84 | O64: 16015 | P64: 17.78s | Q64: 0.117 | R64: 0.55 | S64: Success | T64: =IF(S64="Pending","Pending",IF(AND(S64="Success",Q64<=0.55),"PASS","FAIL")) -> PASS
A65: 12 | B65: Office | C65: Box | D65: 2 | E65: 200 ± 20 lux | F65: Chair, Bag, Shoe, Cup | G65: Yes | H65: Box | I65: move to the Box | J65: Box | K65: Y | L65: 1843 | M65: 370 | N65: 58 | O65: 14210 | P65: 16.18s | Q65: 0.207 | R65: 0.55 | S65: Success | T65: =IF(S65="Pending","Pending",IF(AND(S65="Success",Q65<=0.55),"PASS","FAIL")) -> PASS
A66: 13 | B66: Office | C66: Box | D66: 3 | E66: 200 ± 20 lux | F66: Chair, Bag, Shoe, Cup | G66: Yes | H66: Box | I66: navigate to the Box | J66: Box | K66: Y | L66: 1808 | M66: 362 | N66: 58 | O66: 14330 | P66: 16.23s | Q66: 0.175 | R66: 0.55 | S66: Success | T66: =IF(S66="Pending","Pending",IF(AND(S66="Success",Q66<=0.55),"PASS","FAIL")) -> PASS
... A71: 18 | B71: Office | C71: Bag | D71: 3 | E71: 200 ± 20 lux | F71: Chair, Box, Cup | G71: Yes | H71: Bag | I71: navigate to the Bag | J71: Bag | K71: Y | L71: 1827 | M71: 372 | N71: 59 | O71: 21100 | P71: 23.05s | Q71: 0.371 | R71: 0.55 | S71: Success | T71: =IF(S71="Pending","Pending",IF(AND(S71="Success",Q71<=0.55),"PASS","FAIL")) -> PASS
...

Sheet Report
A1: Room: Office Objects: Cup, Box, Shoe, Bag, Notebook Lighting levels: 800 ± 20 lux, 500 ± 20 lux, 200 ± 20 lux Command templates: go to X move to X navigate to X approach X head to X Total: 3 lighting levels × 5 objects × 5 commands = 75 trials
A2: Report
A3: Light level | B3: Object | C3: N | D3: Success Rate | E3: Mean Total Time (s) | F3: SD | G3: 95% CI | H3: Mean LLM (ms) | I3: Mean DINO (ms) | J3: Mean Depth (ms) | K3: Mean Nav (ms) | L3: Mean Final Dist (m)
A4: 800 ± 20 lux | B4: Cup | C4: 5 | D4: =COUNTIF('Basic Objective Test'!T4:T8,"PASS")/ROWS('Basic Objective Test'!T4:T8) -> 1 | E4: {=AVERAGE(VALUE(SUBSTITUTE(INDEX('Basic Objective Test'!P:P,4+(ROW(A1)-1)*5):INDEX('Basic Objective Test'!P:P,8+(ROW(A1)-1)*5),"s","")))} -> 15.46 | F4: {=_xlfn.STDEV.S(VALUE(SUBSTITUTE(INDEX('Basic Objective Test'!P:P,4+(ROW(A1)-1)*5):INDEX('Basic Objective Test'!P:P,8+(ROW(A1)-1)*5),"s","")))} -> 4.9990949 | G4: {="±"&TEXT(_xlfn.CONFIDENCE.T(0.05,_xlfn.STDEV.S(VALUE(SUBSTITUTE(INDEX('Basic Objective Test'!P:P,4+(ROW(A1)-1)*5):INDEX('Basic Objective Test'!P:P,8+(ROW(A1)-1)*5),"s",""))),5),"0.00")&"s"} -> ±6.21s | H4: =AVERAGE(INDEX('Basic Objective Test'!L:L,4+(ROW(A1)-1)*5):INDEX('Basic Objective Test'!L:L,8+(ROW(A1)-1)*5)) -> 3771.6 | I4: =AVERAGE(INDEX('Basic Objective Test'!M:M,4+(ROW(A1)-1)*5):INDEX('Basic Objective Test'!M:M,8+(ROW(A1)-1)*5)) -> 586.6 | J4: =AVERAGE(INDEX('Basic Objective Test'!N:N,4+(ROW(A1)-1)*5):INDEX('Basic Objective Test'!N:N,8+(ROW(A1)-1)*5)) -> 60.8 | K4: =AVERAGE(INDEX('Basic Objective Test'!O:O,4+(ROW(A1)-1)*5):INDEX('Basic Objective Test'!O:O,8+(ROW(A1)-1)*5)) -> 11517 | L4: =AVERAGE(INDEX('Basic Objective Test'!Q:Q,4+(ROW(A1)-1)*5):INDEX('Basic Objective Test'!Q:Q,8+(ROW(A1)-1)*5)) -> 0.3
B5: Shoe | C5: 5 | D5: =COUNTIF('Basic Objective Test'!T9:T13,"PASS")/ROWS('Basic Objective Test'!T9:T13) -> 1 | E5: {=AVERAGE(VALUE(SUBSTITUTE(INDEX('Basic Objective Test'!P:P,4+(ROW(A2)-1)*5):INDEX('Basic Objective Test'!P:P,8+(ROW(A2)-1)*5),"s","")))} -> 21.166 | F5: {=_xlfn.STDEV.S(VALUE(SUBSTITUTE(INDEX('Basic Objective Test'!P:P,4+(ROW(A2)-1)*5):INDEX('Basic Objective Test'!P:P,8+(ROW(A2)-1)*5),"s","")))} -> 0.75048651 | G5: {="±"&TEXT(_xlfn.CONFIDENCE.T(0.05,_xlfn.STDEV.S(VALUE(SUBSTITUTE(INDEX('Basic Objective Test'!P:P,4+(ROW(A2)-1)*5):INDEX('Basic Objective Test'!P:P,8+(ROW(A2)-1)*5),"s",""))),5),"0.00")&"s"} -> ±0.93s | H5: =AVERAGE(INDEX('Basic Objective Test'!L:L,4+(ROW(A2)-1)*5):INDEX('Basic Objective Test'!L:L,8+(ROW(A2)-1)*5)) -> 1922 | I5: =AVERAGE(INDEX('Basic Objective Test'!M:M,4+(ROW(A2)-1)*5):INDEX('Basic Objective Test'!M:M,8+(ROW(A2)-1)*5)) -> 365.6 | J5: =AVERAGE(INDEX('Basic Objective Test'!N:N,4+(ROW(A2)-1)*5):INDEX('Basic Objective Test'!N:N,8+(ROW(A2)-1)*5)) -> 56.2 | K5: =AVERAGE(INDEX('Basic Objective Test'!O:O,4+(ROW(A2)-1)*5):INDEX('Basic Objective Test'!O:O,8+(ROW(A2)-1)*5)) -> 18881.8 | L5: =AVERAGE(INDEX('Basic Objective Test'!Q:Q,4+(ROW(A2)-1)*5):INDEX('Basic Objective Test'!Q:Q,8+(ROW(A2)-1)*5)) -> 0.2232
B6: Box | C6: 5 | D6: =COUNTIF('Basic Objective Test'!T14:T18,"PASS")/ROWS('Basic Objective Test'!T14:T18) -> 1 | E6: {=AVERAGE(VALUE(SUBSTITUTE(INDEX('Basic Objective Test'!P:P,4+(ROW(A3)-1)*5):INDEX('Basic Objective Test'!P:P,8+(ROW(A3)-1)*5),"s","")))} -> 23.176 | F6: {=_xlfn.STDEV.S(VALUE(SUBSTITUTE(INDEX('Basic Objective Test'!P:P,4+(ROW(A3)-1)*5):INDEX('Basic Objective Test'!P:P,8+(ROW(A3)-1)*5),"s","")))} -> 0.98784108 | G6: {="±"&TEXT(_xlfn.CONFIDENCE.T(0.05,_xlfn.STDEV.S(VALUE(SUBSTITUTE(INDEX('Basic Objective Test'!P:P,4+(ROW(A3)-1)*5):INDEX('Basic Objective Test'!P:P,8+(ROW(A3)-1)*5),"s",""))),5),"0.00")&"s"} -> ±1.23s | H6: =AVERAGE(INDEX('Basic Objective Test'!L:L,4+(ROW(A3)-1)*5):INDEX('Basic Objective Test'!L:L,8+(ROW(A3)-1)*5)) -> 1806.4 | I6: =AVERAGE(INDEX('Basic Objective Test'!M:M,4+(ROW(A3)-1)*5):INDEX('Basic Objective Test'!M:M,8+(ROW(A3)-1)*5)) -> 379 | J6: =AVERAGE(INDEX('Basic Objective Test'!N:N,4+(ROW(A3)-1)*5):INDEX('Basic Objective Test'!N:N,8+(ROW(A3)-1)*5)) -> 60.6 | K6: =AVERAGE(INDEX('Basic Objective Test'!O:O,4+(ROW(A3)-1)*5):INDEX('Basic Objective Test'!O:O,8+(ROW(A3)-1)*5)) -> 20955 | L6: =AVERAGE(INDEX('Basic Objective Test'!Q:Q,4+(ROW(A3)-1)*5):INDEX('Basic Objective Test'!Q:Q,8+(ROW(A3)-1)*5)) -> 0.366
B7: Bag | C7: 5 | D7: =COUNTIF('Basic Objective Test'!T19:T23,"PASS")/ROWS('Basic Objective Test'!T19:T23) -> 1 | E7: {=AVERAGE(VALUE(SUBSTITUTE(INDEX('Basic Objective Test'!P:P,4+(ROW(A4)-1)*5):INDEX('Basic Objective Test'!P:P,8+(ROW(A4)-1)*5),"s","")))} -> 18.114 | F7: {=_xlfn.STDEV.S(VALUE(SUBSTITUTE(INDEX('Basic Objective Test'!P:P,4+(ROW(A4)-1)*5):INDEX('Basic Objective Test'!P:P,8+(ROW(A4)-1)*5),"s","")))} -> 1.0143372 | G7: {="±"&TEXT(_xlfn.CONFIDENCE.T(0.05,_xlfn.STDEV.S(VALUE(SUBSTITUTE(INDEX('Basic Objective Test'!P:P,4+(ROW(A4)-1)*5):INDEX('Basic Objective Test'!P:P,8+(ROW(A4)-1)*5),"s",""))),5),"0.00")&"s"} -> ±1.26s | H7: =AVERAGE(INDEX('Basic Objective Test'!L:L,4+(ROW(A4)-1)*5):INDEX('Basic Objective Test'!L:L,8+(ROW(A4)-1)*5)) -> 1974.6 | I7: =AVERAGE(INDEX('Basic Objective Test'!M:M,4+(ROW(A4)-1)*5):INDEX('Basic Objective Test'!M:M,8+(ROW(A4)-1)*5)) -> 460.2 | J7: =AVERAGE(INDEX('Basic Objective Test'!N:N,4+(ROW(A4)-1)*5):INDEX('Basic Objective Test'!N:N,8+(ROW(A4)-1)*5)) -> 61.6 | K7: =AVERAGE(INDEX('Basic Objective Test'!O:O,4+(ROW(A4)-1)*5):INDEX('Basic Objective Test'!O:O,8+(ROW(A4)-1)*5)) -> 15729.8 | L7: =AVERAGE(INDEX('Basic Objective Test'!Q:Q,4+(ROW(A4)-1)*5):INDEX('Basic Objective Test'!Q:Q,8+(ROW(A4)-1)*5)) -> 0.51
B8: Notebook | C8: 5 | D8: =COUNTIF('Basic Objective Test'!T24:T28,"PASS")/ROWS('Basic Objective Test'!T24:T28) -> 1 | E8: {=AVERAGE(VALUE(SUBSTITUTE(INDEX('Basic Objective Test'!P:P,4+(ROW(A5)-1)*5):INDEX('Basic Objective Test'!P:P,8+(ROW(A5)-1)*5),"s","")))} -> 15.548 | F8: {=_xlfn.STDEV.S(VALUE(SUBSTITUTE(INDEX('Basic Objective Test'!P:P,4+(ROW(A5)-1)*5):INDEX('Basic Objective Test'!P:P,8+(ROW(A5)-1)*5),"s","")))} -> 1.1559715 | G8: {="±"&TEXT(_xlfn.CONFIDENCE.T(0.05,_xlfn.STDEV.S(VALUE(SUBSTITUTE(INDEX('Basic Objective Test'!P:P,4+(ROW(A5)-1)*5):INDEX('Basic Objective Test'!P:P,8+(ROW(A5)-1)*5),"s",""))),5),"0.00")&"s"} -> ±1.44s | H8: =AVERAGE(INDEX('Basic Objective Test'!L:L,4+(ROW(A5)-1)*5):INDEX('Basic Objective Test'!L:L,8+(ROW(A5)-1)*5)) -> 1789.6 | I8: =AVERAGE(INDEX('Basic Objective Test'!M:M,4+(ROW(A5)-1)*5):INDEX('Basic Objective Test'!M:M,8+(ROW(A5)-1)*5)) -> 371.4 | J8: =AVERAGE(INDEX('Basic Objective Test'!N:N,4+(ROW(A5)-1)*5):INDEX('Basic Objective Test'!N:N,8+(ROW(A5)-1)*5)) -> 57 | K8: =AVERAGE(INDEX('Basic Objective Test'!O:O,4+(ROW(A5)-1)*5):INDEX('Basic Objective Test'!O:O,8+(ROW(A5)-1)*5)) -> 13191 | L8: =AVERAGE(INDEX('Basic Objective Test'!Q:Q,4+(ROW(A5)-1)*5):INDEX('Basic Objective Test'!Q:Q,8+(ROW(A5)-1)*5)) -> 0.394
A9: 500 ± 20 lux | B9: Cup | C9: 5 | D9: =COUNTIF('Basic Objective Test'!T29:T33,"PASS")/ROWS('Basic Objective Test'!T29:T33) -> 1 | E9: {=AVERAGE(VALUE(SUBSTITUTE(INDEX('Basic Objective Test'!P:P,4+(ROW(A6)-1)*5):INDEX('Basic Objective Test'!P:P,8+(ROW(A6)-1)*5),"s","")))} -> 14.476 | F9: {=_xlfn.STDEV.S(VALUE(SUBSTITUTE(INDEX('Basic Objective Test'!P:P,4+(ROW(A6)-1)*5):INDEX('Basic Objective Test'!P:P,8+(ROW(A6)-1)*5),"s","")))} -> 0.9281864 | G9: {="±"&TEXT(_xlfn.CONFIDENCE.T(0.05,_xlfn.STDEV.S(VALUE(SUBSTITUTE(INDEX('Basic Objective Test'!P:P,4+(ROW(A6)-1)*5):INDEX('Basic Objective Test'!P:P,8+(ROW(A6)-1)*5),"s",""))),5),"0.00")&"s"} -> ±1.15s | H9: =AVERAGE(INDEX('Basic Objective Test'!L:L,4+(ROW(A6)-1)*5):INDEX('Basic Objective Test'!L:L,8+(ROW(A6)-1)*5)) -> 1781.2 | I9: =AVERAGE(INDEX('Basic Objective Test'!M:M,4+(ROW(A6)-1)*5):INDEX('Basic Objective Test'!M:M,8+(ROW(A6)-1)*5)) -> 374.2 | J9: =AVERAGE(INDEX('Basic Objective Test'!N:N,4+(ROW(A6)-1)*5):INDEX('Basic Objective Test'!N:N,8+(ROW(A6)-1)*5)) -> 58.6 | K9: =AVERAGE(INDEX('Basic Objective Test'!O:O,4+(ROW(A6)-1)*5):INDEX('Basic Objective Test'!O:O,8+(ROW(A6)-1)*5)) -> 12223 | L9: =AVERAGE(INDEX('Basic Objective Test'!Q:Q,4+(ROW(A6)-1)*5):INDEX('Basic Objective Test'!Q:Q,8+(ROW(A6)-1)*5)) -> 0.3682
B10: Shoe | C10: 5 | D10: =COUNTIF('Basic Objective Test'!T34:T38,"PASS")/ROWS('Basic Objective Test'!T34:T38) -> 1 | E10: {=AVERAGE(VALUE(SUBSTITUTE(INDEX('Basic Objective Test'!P:P,4+(ROW(A7)-1)*5):INDEX('Basic Objective Test'!P:P,8+(ROW(A7)-1)*5),"s","")))} -> 13.322 | F10: {=_xlfn.STDEV.S(VALUE(SUBSTITUTE(INDEX('Basic Objective Test'!P:P,4+(ROW(A7)-1)*5):INDEX('Basic Objective Test'!P:P,8+(ROW(A7)-1)*5),"s","")))} -> 0.61690356 | G10: {="±"&TEXT(_xlfn.CONFIDENCE.T(0.05,_xlfn.STDEV.S(VALUE(SUBSTITUTE(INDEX('Basic Objective Test'!P:P,4+(ROW(A7)-1)*5):INDEX('Basic Objective Test'!P:P,8+(ROW(A7)-1)*5),"s",""))),5),"0.00")&"s"} -> ±0.77s | H10: =AVERAGE(INDEX('Basic Objective Test'!L:L,4+(ROW(A7)-1)*5):INDEX('Basic Objective Test'!L:L,8+(ROW(A7)-1)*5)) -> 1852.8 | I10: =AVERAGE(INDEX('Basic Objective Test'!M:M,4+(ROW(A7)-1)*5):INDEX('Basic Objective Test'!M:M,8+(ROW(A7)-1)*5)) -> 362 | J10: =AVERAGE(INDEX('Basic Objective Test'!N:N,4+(ROW(A7)-1)*5):INDEX('Basic Objective Test'!N:N,8+(ROW(A7)-1)*5)) -> 58.8 | K10: =AVERAGE(INDEX('Basic Objective Test'!O:O,4+(ROW(A7)-1)*5):INDEX('Basic Objective Test'!O:O,8+(ROW(A7)-1)*5)) -> 11128.8 | L10: =AVERAGE(INDEX('Basic Objective Test'!Q:Q,4+(ROW(A7)-1)*5):INDEX('Basic Objective Test'!Q:Q,8+(ROW(A7)-1)*5)) -> 0.328
B11: Box | C11: 5 | D11: =COUNTIF('Basic Objective Test'!T39:T43,"PASS")/ROWS('Basic Objective Test'!T39:T43) -> 1 | E11: {=AVERAGE(VALUE(SUBSTITUTE(INDEX('Basic Objective Test'!P:P,4+(ROW(A8)-1)*5):INDEX('Basic Objective Test'!P:P,8+(ROW(A8)-1)*5),"s","")))} -> 19.908 | F11: {=_xlfn.STDEV.S(VALUE(SUBSTITUTE(INDEX('Basic Objective Test'!P:P,4+(ROW(A8)-1)*5):INDEX('Basic Objective Test'!P:P,8+(ROW(A8)-1)*5),"s","")))} -> 0.6187649 | G11: {="±"&TEXT(_xlfn.CONFIDENCE.T(0.05,_xlfn.STDEV.S(VALUE(SUBSTITUTE(INDEX('Basic Objective Test'!P:P,4+(ROW(A8)-1)*5):INDEX('Basic Objective Test'!P:P,8+(ROW(A8)-1)*5),"s",""))),5),"0.00")&"s"} -> ±0.77s | H11: =AVERAGE(INDEX('Basic Objective Test'!L:L,4+(ROW(A8)-1)*5):INDEX('Basic Objective Test'!L:L,8+(ROW(A8)-1)*5)) -> 1949.4 | I11: =AVERAGE(INDEX('Basic Objective Test'!M:M,4+(ROW(A8)-1)*5):INDEX('Basic Objective Test'!M:M,8+(ROW(A8)-1)*5)) -> 468.2 | J11: =AVERAGE(INDEX('Basic Objective Test'!N:N,4+(ROW(A8)-1)*5):INDEX('Basic Objective Test'!N:N,8+(ROW(A8)-1)*5)) -> 64.6 | K11: =AVERAGE(INDEX('Basic Objective Test'!O:O,4+(ROW(A8)-1)*5):INDEX('Basic Objective Test'!O:O,8+(ROW(A8)-1)*5)) -> 17704.8 | L11: =AVERAGE(INDEX('Basic Objective Test'!Q:Q,4+(ROW(A8)-1)*5):INDEX('Basic Objective Test'!Q:Q,8+(ROW(A8)-1)*5)) -> 0.2868
B12: Bag | C12: 5 | D12: =COUNTIF('Basic Objective Test'!T44:T48,"PASS")/ROWS('Basic Objective Test'!T44:T48) -> 0.2 | E12: {=AVERAGE(VALUE(SUBSTITUTE(INDEX('Basic Objective Test'!P:P,4+(ROW(A9)-1)*5):INDEX('Basic Objective Test'!P:P,8+(ROW(A9)-1)*5),"s","")))} -> 18.346 | F12: {=_xlfn.STDEV.S(VALUE(SUBSTITUTE(INDEX('Basic Objective Test'!P:P,4+(ROW(A9)-1)*5):INDEX('Basic Objective Test'!P:P,8+(ROW(A9)-1)*5),"s","")))} -> 0.95526436 | G12: {="±"&TEXT(_xlfn.CONFIDENCE.T(0.05,_xlfn.STDEV.S(VALUE(SUBSTITUTE(INDEX('Basic Objective Test'!P:P,4+(ROW(A9)-1)*5):INDEX('Basic Objective Test'!P:P,8+(ROW(A9)-1)*5),"s",""))),5),"0.00")&"s"} -> ±1.19s | H12: =AVERAGE(INDEX('Basic Objective Test'!L:L,4+(ROW(A9)-1)*5):INDEX('Basic Objective Test'!L:L,8+(ROW(A9)-1)*5)) -> 1641.2 | I12: =AVERAGE(INDEX('Basic Objective Test'!M:M,4+(ROW(A9)-1)*5):INDEX('Basic Objective Test'!M:M,8+(ROW(A9)-1)*5)) -> 369 | J12: =AVERAGE(INDEX('Basic Objective Test'!N:N,4+(ROW(A9)-1)*5):INDEX('Basic Objective Test'!N:N,8+(ROW(A9)-1)*5)) -> 58 | K12: =AVERAGE(INDEX('Basic Objective Test'!O:O,4+(ROW(A9)-1)*5):INDEX('Basic Objective Test'!O:O,8+(ROW(A9)-1)*5)) -> 16074.6 | L12: =AVERAGE(INDEX('Basic Objective Test'!Q:Q,4+(ROW(A9)-1)*5):INDEX('Basic Objective Test'!Q:Q,8+(ROW(A9)-1)*5)) -> 0.6244
B13: Notebook | C13: 5 | D13: =COUNTIF('Basic Objective Test'!T49:T53,"PASS")/ROWS('Basic Objective Test'!T49:T53) -> 1 | E13: {=AVERAGE(VALUE(SUBSTITUTE(INDEX('Basic Objective Test'!P:P,4+(ROW(A10)-1)*5):INDEX('Basic Objective Test'!P:P,8+(ROW(A10)-1)*5),"s","")))} -> 17.756 | F13: {=_xlfn.STDEV.S(VALUE(SUBSTITUTE(INDEX('Basic Objective Test'!P:P,4+(ROW(A10)-1)*5):INDEX('Basic Objective Test'!P:P,8+(ROW(A10)-1)*5),"s","")))} -> 1.6702185 | G13: {="±"&TEXT(_xlfn.CONFIDENCE.T(0.05,_xlfn.STDEV.S(VALUE(SUBSTITUTE(INDEX('Basic Objective Test'!P:P,4+(ROW(A10)-1)*5):INDEX('Basic Objective Test'!P:P,8+(ROW(A10)-1)*5),"s",""))),5),"0.00")&"s"} -> ±2.07s | H13: =AVERAGE(INDEX('Basic Objective Test'!L:L,4+(ROW(A10)-1)*5):INDEX('Basic Objective Test'!L:L,8+(ROW(A10)-1)*5)) -> 1735.8 | I13: =AVERAGE(INDEX('Basic Objective Test'!M:M,4+(ROW(A10)-1)*5):INDEX('Basic Objective Test'!M:M,8+(ROW(A10)-1)*5)) -> 369.8 | J13: =AVERAGE(INDEX('Basic Objective Test'!N:N,4+(ROW(A10)-1)*5):INDEX('Basic Objective Test'!N:N,8+(ROW(A10)-1)*5)) -> 58.6 | K13: =AVERAGE(INDEX('Basic Objective Test'!O:O,4+(ROW(A10)-1)*5):INDEX('Basic Objective Test'!O:O,8+(ROW(A10)-1)*5)) -> 15482.6 | L13: =AVERAGE(INDEX('Basic Objective Test'!Q:Q,4+(ROW(A10)-1)*5):INDEX('Basic Objective Test'!Q:Q,8+(ROW(A10)-1)*5)) -> 0.3198
A14: 200 ± 20 lux | B14: Cup | C14: 5 | D14: =COUNTIF('Basic Objective Test'!T54:T58,"PASS")/ROWS('Basic Objective Test'!T54:T58) -> 1 | E14: {=AVERAGE(VALUE(SUBSTITUTE(INDEX('Basic Objective Test'!P:P,4+(ROW(A11)-1)*5):INDEX('Basic Objective Test'!P:P,8+(ROW(A11)-1)*5),"s","")))} -> 16.582 | F14: {=_xlfn.STDEV.S(VALUE(SUBSTITUTE(INDEX('Basic Objective Test'!P:P,4+(ROW(A11)-1)*5):INDEX('Basic Objective Test'!P:P,8+(ROW(A11)-1)*5),"s","")))} -> 4.1219377 | G14: {="±"&TEXT(_xlfn.CONFIDENCE.T(0.05,_xlfn.STDEV.S(VALUE(SUBSTITUTE(INDEX('Basic Objective Test'!P:P,4+(ROW(A11)-1)*5):INDEX('Basic Objective Test'!P:P,8+(ROW(A11)-1)*5),"s",""))),5),"0.00")&"s"} -> ±5.12s | H14: =AVERAGE(INDEX('Basic Objective Test'!L:L,4+(ROW(A11)-1)*5):INDEX('Basic Objective Test'!L:L,8+(ROW(A11)-1)*5)) -> 2984.6 | I14: =AVERAGE(INDEX('Basic Objective Test'!M:M,4+(ROW(A11)-1)*5):INDEX('Basic Objective Test'!M:M,8+(ROW(A11)-1)*5)) -> 512.6 | J14: =AVERAGE(INDEX('Basic Objective Test'!N:N,4+(ROW(A11)-1)*5):INDEX('Basic Objective Test'!N:N,8+(ROW(A11)-1)*5)) -> 64.4 | K14: =AVERAGE(INDEX('Basic Objective Test'!O:O,4+(ROW(A11)-1)*5):INDEX('Basic Objective Test'!O:O,8+(ROW(A11)-1)*5)) -> 13822.6 | L14: =AVERAGE(INDEX('Basic Objective Test'!Q:Q,4+(ROW(A11)-1)*5):INDEX('Basic Objective Test'!Q:Q,8+(ROW(A11)-1)*5)) -> 0.3568
B15: Shoe | C15: 5 | D15: =COUNTIF('Basic Objective Test'!T59:T63,"PASS")/ROWS('Basic Objective Test'!T59:T63) -> 1 | E15: {=AVERAGE(VALUE(SUBSTITUTE(INDEX('Basic Objective Test'!P:P,4+(ROW(A12)-1)*5):INDEX('Basic Objective Test'!P:P,8+(ROW(A12)-1)*5),"s","")))} -> 20.742 | F15: {=_xlfn.STDEV.S(VALUE(SUBSTITUTE(INDEX('Basic Objective Test'!P:P,4+(ROW(A12)-1)*5):INDEX('Basic Objective Test'!P:P,8+(ROW(A12)-1)*5),"s","")))} -> 2.5469335 | G15: {="±"&TEXT(_xlfn.CONFIDENCE.T(0.05,_xlfn.STDEV.S(VALUE(SUBSTITUTE(INDEX('Basic Objective Test'!P:P,4+(ROW(A12)-1)*5):INDEX('Basic Objective Test'!P:P,8+(ROW(A12)-1)*5),"s",""))),5),"0.00")&"s"} -> ±3.16s | H15: =AVERAGE(INDEX('Basic Objective Test'!L:L,4+(ROW(A12)-1)*5):INDEX('Basic Objective Test'!L:L,8+(ROW(A12)-1)*5)) -> 3224.6 | I15: =AVERAGE(INDEX('Basic Objective Test'!M:M,4+(ROW(A12)-1)*5):INDEX('Basic Objective Test'!M:M,8+(ROW(A12)-1)*5)) -> 376.6 | J15: =AVERAGE(INDEX('Basic Objective Test'!N:N,4+(ROW(A12)-1)*5):INDEX('Basic Objective Test'!N:N,8+(ROW(A12)-1)*5)) -> 58.6 | K15: =AVERAGE(INDEX('Basic Objective Test'!O:O,4+(ROW(A12)-1)*5):INDEX('Basic Objective Test'!O:O,8+(ROW(A12)-1)*5)) -> 17027.8 | L15: =AVERAGE(INDEX('Basic Objective Test'!Q:Q,4+(ROW(A12)-1)*5):INDEX('Basic Objective Test'!Q:Q,8+(ROW(A12)-1)*5)) -> 0.265
B16: Box | C16: 5 | D16: =COUNTIF('Basic Objective Test'!T64:T68,"PASS")/ROWS('Basic Objective Test'!T64:T68) -> 1 | E16: {=AVERAGE(VALUE(SUBSTITUTE(INDEX('Basic Objective Test'!P:P,4+(ROW(A13)-1)*5):INDEX('Basic Objective Test'!P:P,8+(ROW(A13)-1)*5),"s","")))} -> 16.394 | F16: {=_xlfn.STDEV.S(VALUE(SUBSTITUTE(INDEX('Basic Objective Test'!P:P,4+(ROW(A13)-1)*5):INDEX('Basic Objective Test'!P:P,8+(ROW(A13)-1)*5),"s","")))} -> 0.86918352 | G16: {="±"&TEXT(_xlfn.CONFIDENCE.T(0.05,_xlfn.STDEV.S(VALUE(SUBSTITUTE(INDEX('Basic Objective Test'!P:P,4+(ROW(A13)-1)*5):INDEX('Basic Objective Test'!P:P,8+(ROW(A13)-1)*5),"s",""))),5),"0.00")&"s"} -> ±1.08s | H16: =AVERAGE(INDEX('Basic Objective Test'!L:L,4+(ROW(A13)-1)*5):INDEX('Basic Objective Test'!L:L,8+(ROW(A13)-1)*5)) -> 1791.6 | I16: =AVERAGE(INDEX('Basic Objective Test'!M:M,4+(ROW(A13)-1)*5):INDEX('Basic Objective Test'!M:M,8+(ROW(A13)-1)*5)) -> 493.8 | J16: =AVERAGE(INDEX('Basic Objective Test'!N:N,4+(ROW(A13)-1)*5):INDEX('Basic Objective Test'!N:N,8+(ROW(A13)-1)*5)) -> 63.4 | K16: =AVERAGE(INDEX('Basic Objective Test'!O:O,4+(ROW(A13)-1)*5):INDEX('Basic Objective Test'!O:O,8+(ROW(A13)-1)*5)) -> 14213.4 | L16: =AVERAGE(INDEX('Basic Objective Test'!Q:Q,4+(ROW(A13)-1)*5):INDEX('Basic Objective Test'!Q:Q,8+(ROW(A13)-1)*5)) -> 0.2288
B17: Bag | C17: 5 | D17: =COUNTIF('Basic Objective Test'!T69:T73,"PASS")/ROWS('Basic Objective Test'!T69:T73) -> 0.8 | E17: {=AVERAGE(VALUE(SUBSTITUTE(INDEX('Basic Objective Test'!P:P,4+(ROW(A14)-1)*5):INDEX('Basic Objective Test'!P:P,8+(ROW(A14)-1)*5),"s","")))} -> 22.588 | F17: {=_xlfn.STDEV.S(VALUE(SUBSTITUTE(INDEX('Basic Objective Test'!P:P,4+(ROW(A14)-1)*5):INDEX('Basic Objective Test'!P:P,8+(ROW(A14)-1)*5),"s","")))} -> 1.5746015 | G17: {="±"&TEXT(_xlfn.CONFIDENCE.T(0.05,_xlfn.STDEV.S(VALUE(SUBSTITUTE(INDEX('Basic Objective Test'!P:P,4+(ROW(A14)-1)*5):INDEX('Basic Objective Test'!P:P,8+(ROW(A14)-1)*5),"s",""))),5),"0.00")&"s"} -> ±1.96s | H17: =AVERAGE(INDEX('Basic Objective Test'!L:L,4+(ROW(A14)-1)*5):INDEX('Basic Objective Test'!L:L,8+(ROW(A14)-1)*5)) -> 1813.8 | I17: =AVERAGE(INDEX('Basic Objective Test'!M:M,4+(ROW(A14)-1)*5):INDEX('Basic Objective Test'!M:M,8+(ROW(A14)-1)*5)) -> 373 | J17: =AVERAGE(INDEX('Basic Objective Test'!N:N,4+(ROW(A14)-1)*5):INDEX('Basic Objective Test'!N:N,8+(ROW(A14)-1)*5)) -> 59.2 | K17: =AVERAGE(INDEX('Basic Objective Test'!O:O,4+(ROW(A14)-1)*5):INDEX('Basic Objective Test'!O:O,8+(ROW(A14)-1)*5)) -> 20430.4 | L17: =AVERAGE(INDEX('Basic Objective Test'!Q:Q,4+(ROW(A14)-1)*5):INDEX('Basic Objective Test'!Q:Q,8+(ROW(A14)-1)*5)) -> 0.4162
B18: Notebook | C18: 5 | D18: =COUNTIF('Basic Objective Test'!T74:T78,"PASS")/ROWS('Basic Objective Test'!T74:T78) -> 1 | E18: {=AVERAGE(VALUE(SUBSTITUTE(INDEX('Basic Objective Test'!P:P,4+(ROW(A15)-1)*5):INDEX('Basic Objective Test'!P:P,8+(ROW(A15)-1)*5),"s","")))} -> 15.766 | F18: {=_xlfn.STDEV.S(VALUE(SUBSTITUTE(INDEX('Basic Objective Test'!P:P,4+(ROW(A15)-1)*5):INDEX('Basic Objective Test'!P:P,8+(ROW(A15)-1)*5),"s","")))} -> 0.31918647 | G18: {="±"&TEXT(_xlfn.CONFIDENCE.T(0.05,_xlfn.STDEV.S(VALUE(SUBSTITUTE(INDEX('Basic Objective Test'!P:P,4+(ROW(A15)-1)*5):INDEX('Basic Objective Test'!P:P,8+(ROW(A15)-1)*5),"s",""))),5),"0.00")&"s"} -> ±0.40s | H18: =AVERAGE(INDEX('Basic Objective Test'!L:L,4+(ROW(A15)-1)*5):INDEX('Basic Objective Test'!L:L,8+(ROW(A15)-1)*5)) -> 1645 | I18: =AVERAGE(INDEX('Basic Objective Test'!M:M,4+(ROW(A15)-1)*5):INDEX('Basic Objective Test'!M:M,8+(ROW(A15)-1)*5)) -> 364.6 | J18: =AVERAGE(INDEX('Basic Objective Test'!N:N,4+(ROW(A15)-1)*5):INDEX('Basic Objective Test'!N:N,8+(ROW(A15)-1)*5)) -> 57 | K18: =AVERAGE(INDEX('Basic Objective Test'!O:O,4+(ROW(A15)-1)*5):INDEX('Basic Objective Test'!O:O,8+(ROW(A15)-1)*5)) -> 13651.2 | L18: =AVERAGE(INDEX('Basic Objective Test'!Q:Q,4+(ROW(A15)-1)*5):INDEX('Basic Objective Test'!Q:Q,8+(ROW(A15)-1)*5)) -> 0.2886
A19: Overall success rate | B19: =COUNTIF('Basic Objective Test'!T4:T78,"PASS")&"/"&ROWS('Basic Objective Test'!T4:T78)&" = "&TEXT(COUNTIF('Basic Objective Test'!T4:T78,"PASS")/ROWS('Basic Objective Test'!T4:T78),"0.0%") -> 70/75 = 93.3%

Sheet Robustness Test

Sheet Basic Objective Test (2)
A1: PuzzleBot LLM–VLM–ROS2 | Basic Objective Test Plan (20 Trials)
A2: 1.LLM Latency (ms): Time taken to convert the natural language command into a structured navigation intent and target label. 2.DINO Latency (ms): Time when the target is successfully detected for the first time 3.Depth Latency (ms): Time when the target was successfully detected for the first time based on depth estimation from the image 4.Nav Total Latency (ms): The total navigation time from receiving the target at the navigation_node and starting navigation to the robot determining whether it has arrived or stopped. 5.Total time (s): Measure the total end-to-end time from the start of the input command to the robot's final stop. 6.Final Dist to Target (m): Measure the straight-line distance between the robot and the actual target object when the robot stops.
A3: Trial # | B3: Room Type | C3: Condition Group | D3: Rep # | E3: Lighting Condition | F3: Lighting (lux)(use LightMeterApp) | G3: Target Object | H3: Natural Language Command | I3: LLM Extracted Label | J3: Label Match? (Y/N) | K3: LLM Latency (ms) | L3: DINO Latency (ms) | M3: Depth Latency (ms) | N3: Nav Total Latency (ms) | O3: Toal time(s) | P3: Final Dist to Target (m) | Q3: Dist Threshold (m) | R3: Trial Result | S3: PASS / FAIL | T3: Observations & Notes
A4: 1 | B4: Bedroom | C4: Cup + Bright | D4: 1 | E4: Bright | F4: 800 ± 20 lux | G4: Cup | H4: go to the Cup | I4: Cup | J4: Y | K4: 7005 | L4: 337 | M4: 55 | N4: 15320 | O4: 22.8 | P4: 0.267 | Q4: 0.5 | R4: Success | S4: =IF(R4="Pending","Pending",IF(AND(R4="Success",P4<=0.5),"PASS","FAIL")) -> PASS
A5: 2 | B5: Bedroom | C5: Cup + Bright | D5: 2 | E5: Bright | F5: 800 ± 20 lux | G5: Cup | H5: move to the Cup | I5: Cup | J5: Y | K5: 6363 | L5: 337 | M5: 55 | N5: 18263 | O5: 25.03 | P5: 0.05 | Q5: 0.5 | R5: Success | S5: =IF(R5="Pending","Pending",IF(AND(R5="Success",P5<=0.5),"PASS","FAIL")) -> PASS
A6: 3 | B6: Bedroom | C6: Cup + Bright | D6: 3 | E6: Bright | F6: 800 ± 20 lux | G6: Cup | H6: navigate to the Cup | I6: Cup | J6: Y | K6: 6328 | L6: 337 | M6: 55 | N6: 23742 | O6: 30.31 | P6: 0.17 | Q6: 0.5 | R6: Success | S6: =IF(R6="Pending","Pending",IF(AND(R6="Success",P6<=0.5),"PASS","FAIL")) -> PASS
A7: 4 | B7: Bedroom | C7: Cup + Bright | D7: 4 | E7: Bright | F7: 800 ± 20 lux | G7: Cup | H7: approach the Cup | I7: Cup | J7: Y | K7: 6228 | L7: 334 | M7: 55 | N7: 18398 | O7: 25.02 | P7: 0.22 | Q7: 0.5 | R7: Success | S7: =IF(R7="Pending","Pending",IF(AND(R7="Success",P7<=0.5),"PASS","FAIL")) -> PASS
A8: 5 | B8: Bedroom | C8: Cup + Bright | D8: 5 | E8: Bright | F8: 800 ± 20 lux | G8: Cup | H8: head to the Cup | I8: Cup | J8: Y | K8: 5803 | L8: 338 | M8: 55 | N8: 19184 | O8: 25.48 | P8: 0.148 | Q8: 0.5 | R8: Success | S8: =IF(R8="Pending","Pending",IF(AND(R8="Success",P8<=0.5),"PASS","FAIL")) -> PASS
A9: 6 | B9: Bedroom | C9: Shoe + Bright | D9: 1 | E9: Bright | F9: 800 ± 20 lux | G9: Shoe | H9: go to the Shoe | I9: Shoe | J9: Y | K9: 6756 | L9: 329 | M9: 54 | N9: 15131 | O9: 22.27 | P9: 0.32 | Q9: 0.5 | R9: Success | S9: =IF(R9="Pending","Pending",IF(AND(R9="Success",P9<=0.5),"PASS","FAIL")) -> PASS
A10: 7 | B10: Bedroom | C10: Shoe + Bright | D10: 2 | E10: Bright | F10: 800 ± 20 lux | G10: Shoe | H10: move to the Shoe | I10: Shoe | J10: Y | K10: 1682 | L10: 329 | M10: 55 | N10: 15578 | O10: 17.53 | P10: 0.18 | Q10: 0.5 | R10: Success | S10: =IF(R10="Pending","Pending",IF(AND(R10="Success",P10<=0.5),"PASS","FAIL")) -> PASS
A11: 8 | B11: Bedroom | C11: Shoe + Bright | D11: 3 | E11: Bright | F11: 800 ± 20 lux | G11: Shoe | H11: navigate to the Shoe | I11: Shoe | J11: Y | K11: 1743 | L11: 333 | M11: 55 | N11: 14299 | O11: 16.43 | P11: 0.278 | Q11: 0.5 | R11: Success | S11: =IF(R11="Pending","Pending",IF(AND(R11="Success",P11<=0.5),"PASS","FAIL")) -> PASS
A12: 9 | B12: Bedroom | C12: Shoe + Bright | D12: 4 | E12: Bright | F12: 800 ± 20 lux | G12: Shoe | H12: approach the Shoe | I12: Shoe | J12: Y | K12: 1642 | L12: 330 | M12: 55 | N12: 14573 | O12: 16.6 | P12: 0.19 | Q12: 0.5 | R12: Success | S12: =IF(R12="Pending","Pending",IF(AND(R12="Success",P12<=0.5),"PASS","FAIL")) -> PASS
A13: 10 | B13: Bedroom | C13: Shoe + Bright | D13: 5 | E13: Bright | F13: 800 ± 20 lux | G13: Shoe | H13: head to the Shoe | I13: Shoe | J13: Y | K13: 1667 | L13: 372 | M13: 58 | N13: 16103 | O13: 18.2 | P13: 0.165 | Q13: 0.5 | R13: Success | S13: =IF(R13="Pending","Pending",IF(AND(R13="Success",P13<=0.5),"PASS","FAIL")) -> PASS
A14: 11 | B14: Bedroom | C14: Box + Bright | D14: 1 | E14: Bright | F14: 800 ± 20 lux | G14: Box | H14: go to the Box | I14: Box | J14: Y | K14: 6832 | L14: 328 | M14: 55 | N14: 20905 | O14: 28.12 | P14: 0.366 | Q14: 0.5 | R14: Success | S14: =IF(R14="Pending","Pending",IF(AND(R14="Success",P14<=0.5),"PASS","FAIL")) -> PASS
A15: 12 | B15: Bedroom | C15: Box + Bright | D15: 2 | E15: Bright | F15: 800 ± 20 lux | G15: Box | H15: move to the Box | I15: Box | J15: Y | K15: 6489 | L15: 328 | M15: 55 | N15: 19398 | O15: 26.27 | P15: 0.361 | Q15: 0.5 | R15: Success | S15: =IF(R15="Pending","Pending",IF(AND(R15="Success",P15<=0.5),"PASS","FAIL")) -> PASS
... A28: 25 | B28: Bedroom | C28: Chair + Bright | D28: 5 | E28: Bright | F28: 800 ± 20 lux | G28: Chair | H28: head to the Chair | I28: Chair | J28: Y | K28: 1690 | L28: 364 | M28: 57 | N28: 18959 | O28: 21.27 | P28: 0.821 | Q28: 0.5 | R28: Success | S28: =IF(R28="Pending","Pending",IF(AND(R28="Success",P28<=0.5),"PASS","FAIL")) -> FAIL
A29: 26 | B29: Bedroom | C29: Cup + Normal | D29: 1 | E29: Normal | F29: 350 ± 20 lux | G29: Cup | H29: go to the Cup | I29: Cup | J29: Y | Q29: 0.5 | R29: Pending | S29: =IF(R29="Pending","Pending",IF(AND(R29="Success",P29<=0.5),"PASS","FAIL")) -> Pending | T29: 1.826m
A30: 27 | B30: Bedroom | C30: Cup + Normal | D30: 2 | E30: Normal | F30: 350 ± 20 lux | G30: Cup | H30: move to the Cup | I30: Cup | J30: Y | Q30: 0.5 | R30: Pending | S30: =IF(R30="Pending","Pending",IF(AND(R30="Success",P30<=0.5),"PASS","FAIL")) -> Pending
A31: 28 | B31: Bedroom | C31: Cup + Normal | D31: 3 | E31: Normal | F31: 350 ± 20 lux | G31: Cup | H31: navigate to the Cup | I31: Cup | J31: Y | Q31: 0.5 | R31: Pending | S31: =IF(R31="Pending","Pending",IF(AND(R31="Success",P31<=0.5),"PASS","FAIL")) -> Pending
A32: 29 | B32: Bedroom | C32: Cup + Normal | D32: 4 | E32: Normal | F32: 350 ± 20 lux | G32: Cup | H32: approach the Cup | I32: Cup | J32: Y | Q32: 0.5 | R32: Pending | S32: =IF(R32="Pending","Pending",IF(AND(R32="Success",P32<=0.5),"PASS","FAIL")) -> Pending
A33: 30 | B33: Bedroom | C33: Cup + Normal | D33: 5 | E33: Normal | F33: 350 ± 20 lux | G33: Cup | H33: head to the Cup | I33: Cup | J33: Y | Q33: 0.5 | R33: Pending | S33: =IF(R33="Pending","Pending",IF(AND(R33="Success",P33<=0.5),"PASS","FAIL")) -> Pending
A34: 31 | B34: Bedroom | C34: Shoe + Normal | D34: 1 | E34: Normal | F34: 350 ± 20 lux | G34: Shoe | H34: go to the Shoe | I34: Shoe | J34: Y | Q34: 0.5 | R34: Pending | S34: =IF(R34="Pending","Pending",IF(AND(R34="Success",P34<=0.5),"PASS","FAIL")) -> Pending
A35: 32 | B35: Bedroom | C35: Shoe + Normal | D35: 2 | E35: Normal | F35: 350 ± 20 lux | G35: Shoe | H35: move to the Shoe | I35: Shoe | J35: Y | Q35: 0.5 | R35: Pending | S35: =IF(R35="Pending","Pending",IF(AND(R35="Success",P35<=0.5),"PASS","FAIL")) -> Pending
A36: 33 | B36: Bedroom | C36: Shoe + Normal | D36: 3 | E36: Normal | F36: 350 ± 20 lux | G36: Shoe | H36: navigate to the Shoe | I36: Shoe | J36: Y | Q36: 0.5 | R36: Pending | S36: =IF(R36="Pending","Pending",IF(AND(R36="Success",P36<=0.5),"PASS","FAIL")) -> Pending
A37: 34 | B37: Bedroom | C37: Shoe + Normal | D37: 4 | E37: Normal | F37: 350 ± 20 lux | G37: Shoe | H37: approach the Shoe | I37: Shoe | J37: Y | Q37: 0.5 | R37: Pending | S37: =IF(R37="Pending","Pending",IF(AND(R37="Success",P37<=0.5),"PASS","FAIL")) -> Pending
A38: 35 | B38: Bedroom | C38: Shoe + Normal | D38: 5 | E38: Normal | F38: 350 ± 20 lux | G38: Shoe | H38: head to the Shoe | I38: Shoe | J38: Y | Q38: 0.5 | R38: Pending | S38: =IF(R38="Pending","Pending",IF(AND(R38="Success",P38<=0.5),"PASS","FAIL")) -> Pending
A39: 36 | B39: Bedroom | C39: Box + Normal | D39: 1 | E39: Normal | F39: 350 ± 20 lux | G39: Box | H39: go to the Box | I39: Box | J39: Y | Q39: 0.5 | R39: Pending | S39: =IF(R39="Pending","Pending",IF(AND(R39="Success",P39<=0.5),"PASS","FAIL")) -> Pending
A40: 37 | B40: Bedroom | C40: Box + Normal | D40: 2 | E40: Normal | F40: 350 ± 20 lux | G40: Box | H40: move to the Box | I40: Box | J40: Y | Q40: 0.5 | R40: Pending | S40: =IF(R40="Pending","Pending",IF(AND(R40="Success",P40<=0.5),"PASS","FAIL")) -> Pending
A41: 38 | B41: Bedroom | C41: Box + Normal | D41: 3 | E41: Normal | F41: 350 ± 20 lux | G41: Box | H41: navigate to the Box | I41: Box | J41: Y | Q41: 0.5 | R41: Pending | S41: =IF(R41="Pending","Pending",IF(AND(R41="Success",P41<=0.5),"PASS","FAIL")) -> Pending
... A53: 50 | B53: Bedroom | C53: Chair + Normal | D53: 5 | E53: Normal | F53: 350 ± 20 lux | G53: Chair | H53: head to the Chair | I53: Chair | J53: Y | Q53: 0.5 | R53: Pending | S53: =IF(R53="Pending","Pending",IF(AND(R53="Success",P53<=0.5),"PASS","FAIL")) -> Pending
